<robot name="my_robot">
    <link name = "base_footprint">
        <visual>
        <geometry>
            <sphere radius="0.01"/>
        </geometry>
        </visual>
        </link>
    <link name = "base_link">
        <visual>
            <geometry>
                <box size ="0.3 0.215 0.000187" />
            </geometry>
            <origin xyz="0 0 0" rpy="0 0 0"/>
                <material name = "yellow">
                <color rgba="1 1 0 1" />
                </material>
        </visual>
      
        </link>    
    <joint name = "base_link2base_footprint" type="fixed">
        <parent link = "base_footprint"/>
        <child link= "base_link"/>
        <origin xyz="0 0 0.067"/>

    </joint>
    
    <link name="a_wheel">
        <visual>
            <geometry>
                <cylinder radius="0.0324" length="0.027"/>
            </geometry>
            <origin xyz="0 0 0" rpy="1.5705 0 0"/>
            <material name ="black">
                <color rgba ="0 0 0 1"/>
            </material>
        </visual>
    </link>


    <joint name="a_wheel2base_link" type ="continuous">
        <parent link="base_link"/>
        <child link="a_wheel"/>
        <origin xyz="-0.08 0.132 -0.0324"/>
        <axis xyz="0 1 0"/>
    </joint>

    <link name="b_wheel">
        <visual>
            <geometry>
                <cylinder radius="0.0324" length="0.027"/>
            </geometry>
            <origin xyz="0 0 0" rpy="1.5705 0 0"/>
            <material name ="black">
                <color rgba ="0 0 0 1"/>
            </material>
        </visual>
    </link>


    <joint name="b_wheel2base_link" type ="continuous">
        <parent link="base_link"/>
        <child link="b_wheel"/>
        <origin xyz="0.08 0.132 -0.0324"/>
        <axis xyz="0 1 0"/>
    </joint>


    
    <link name="c_wheel">
        <visual>
            <geometry>
                <cylinder radius="0.0324" length="0.027"/>
            </geometry>
            <origin xyz="0 0 0" rpy="1.5705 0 0"/>
            <material name ="black">
                <color rgba ="0 0 0 1"/>
            </material>
        </visual>
    </link>


    <joint name="c_wheel2base_link" type ="continuous">
        <parent link="base_link"/>
        <child link="c_wheel"/>
        <origin xyz="0.08 -0.132 -0.0324"/>
        <axis xyz="0 1 0"/>
    </joint>

    
    <link name="d_wheel">
        <visual>
            <geometry>
                <cylinder radius="0.0324" length="0.027"/>
            </geometry>
            <origin xyz="0 0 0" rpy="1.5705 0 0"/>
            <material name ="black">
                <color rgba ="0 0 0 1"/>
            </material>
        </visual>
    </link>


    <joint name="d_wheel2base_link" type ="continuous">
        <parent link="base_link"/>
        <child link="d_wheel"/>
        <origin xyz="-0.08 -0.132 -0.0324"/>
        <axis xyz="0 1 0"/>
    </joint>


    <link name="support_laser">
        <visual>
        <geometry>
            <cylinder radius = "0.01" length="0.055"/>
        </geometry>
        <origin xyz="0 0 0" rpy="0 0 0"/>
        <material name ="white">
            <color rgba="1.0 1.0 1.0 1.0"/>
        </material>

        </visual>
        </link>
    <joint name = "support_laser2base_link" type="fixed">
    <parent link="base_link"/>
    <child  link="support_laser"/>
    <origin xyz="-0.09 0 0.035"/>
    </joint>
    <link name="laser">
    <visual>
        <geometry>
            <cylinder radius= "0.04" length="0.04"/>
        </geometry>
        <origin xyz="0 0 0" rpy="0 0 0"/>
        <material name="violet">
        <color rgba="1 1 1 0.5"/>
        </material>
        </visual>
    </link>
    
    <joint name="laser2support_laser" type="continuous">
        <parent link="support_laser" />
        <child link="laser"/>
        <origin xyz="0 0 0.0475" rpy="0 0 3.14"/>
        <axis xyz="0 0 1"/>    
    </joint>

    <link name ="raspberryPi">
    <visual>
    <geometry >
    <box size="0.1 0.07 0.03"/>
    </geometry>
    <origin xyz="0 0 0" rpy="0 0 1.57"/>
    <material name="white2">
    <color rgba="0.8 0.8 0.8 1"/>
    </material>
    </visual>
    </link>
    <joint name="raspberryPi2base_link" type="fixed">
    <parent link="base_link"/>
    <child  link="raspberryPi"/>
    <origin xyz="0.09 0 0.025"/>
    </joint>

    <link name="stm32control">
    <visual>
    <geometry>
    <box size="0.08 0.06 0.007"/>
    </geometry>
    <material name="green">
    <color rgba="0 0.5 0 1"/>
    </material>
    </visual>
    </link>
    
    <joint name="stm32control2base_link" type="fixed">
    <parent link="base_link"/>
    <child  link="stm32control"/>
    <origin xyz="0 0.06 0.0135"/>
    </joint>


    <link  name="powerDriver">
    <visual>
    <geometry>
    <box size= "0.08 0.06 0.007"/>
    </geometry>
    <origin xyz="0 0 0" rpy="0 0 0"/>
    <material name="green">
    <color rgba="0 0.5 0 1"/>
    </material>
    </visual>
    </link>

    <joint name="powerDriver2_base_link" type="fixed">
    <parent link = "base_link"/>
    <child link= "powerDriver"/>
    <origin xyz="0 -0.06 0.0135"/>
    </joint>


    <link name ="gyro_link">
    <visual>
    <geometry >
    <box size="0.005 0.005 0.001"/>
    </geometry>
    <origin xyz="0 0 0" rpy="0 0 0"/>
    <material name="black">
    <color rgba="0 0 0 0.8"/>
    </material>
    </visual>
    </link>

    <joint name="gyro_link2stm32conroller" type="fixed">
    <parent link = "stm32control"/>
    <child link ="gyro_link"/>
    <origin xyz="0 -0.01 0.004"/>
    </joint>
    </robot>